Workbook

Sheet Сравнение-старыеW-новыеW
A1: Пункт отправления | B1: Пункт назначения | C1: Фиксированные тарифы | F1: Вес (кг) | M1: Объём (м³)
T2: Вес ( кг ) | U2: Услуга | V2: 0 - 5 | W2: 5,01 - 20 | X2: 20,01 - 41 | Y2: 41,01 -100 | Z2: 100,01 - 300 | AA2: 300,01 - 500 | AB2: 500,01 - 650 | AC2: 650,001 - 800 | AD2: 800,01 - 1000 | AE2: 1000,01 - 1500 | AF2: 1500,01 - 2000 | AG2: 2000,01 - 3000 | AH2: 3000,01 - 5000 | AI2: 5000,01 - 6000 | AJ2: 6000,01 - 8000 | AK2: 8000,01 - 10000 | AL2: 10000,01 - 20000
C3: до 5 кг | D3: до 20 кг | E3: до 40 кг | F3: от | G3: 2000- | H3: 1000- | I3: 500- | J3: 200- | K3: 100- | L3: 41 | M3: от | N3: 10- | O3: 5- | P3: 3- | Q3: 1- | R3: 0,2-
C4: до 0,03 м3 | D4: до 0,1 м3 | E4: до 0,19 м3 | F4: 3000 | G4: 2999 | H4: 1999 | I4: 999 | J4: 499 | K4: 199 | L4: 99 | M4: 15 | N4: 14.9 | O4: 9.9 | P4: 4.9 | Q4: 2.9 | R4: 0.99 | T4: Объем ( м3 ) | V4: 0 - 0,1 | W4: 0,11 - 0,15 | X4: 0,16 - 0,19 | Y4: 0,2 - 0,8 | Z4: 0.81 - 1,8 | AA4: 1,81 - 2,5 | AB4: 2,51 - 3 | AC4: 3,01 - 4,99 | AD4: 5 - 5,99 | AE4: 6 - 7,95 | AF4: 7,96 - 10 | AG4: 10,01 - 11,99 | AH4: 12 - 14,99 | AI4: 15 - 19,99 | AJ4: 20 - 22 | AK4: 22,01 - 34,99 | AL4: 35 - 82
A7: Исторические и исходные объёмные тарифы не загружены. Текущие веса — на листе WernerNEW.

Sheet новыеW
A1: Пункт отправления | B1: Пункт назначения | C1: Фиксированные тарифы | F1: Вес (кг) | M1: Объём (м³)
T2: Вес ( кг ) | U2: Услуга | V2: 0 - 5 | W2: 5,01 - 20 | X2: 20,01 - 41 | Y2: 41,01 -100 | Z2: 100,01 - 300 | AA2: 300,01 - 500 | AB2: 500,01 - 650 | AC2: 650,001 - 800 | AD2: 800,01 - 1000 | AE2: 1000,01 - 1500 | AF2: 1500,01 - 2000 | AG2: 2000,01 - 3000 | AH2: 3000,01 - 5000 | AI2: 5000,01 - 6000 | AJ2: 6000,01 - 8000 | AK2: 8000,01 - 10000 | AL2: 10000,01 - 20000
C3: до 5 кг | D3: до 20 кг | E3: до 40 кг | F3: от | G3: 2000- | H3: 1000- | I3: 500- | J3: 200- | K3: 100- | L3: 41 | M3: от | N3: 10- | O3: 5- | P3: 3- | Q3: 1- | R3: 0,2-
C4: до 0,03 м3 | D4: до 0,1 м3 | E4: до 0,19 м3 | F4: 3000 | G4: 2999 | H4: 1999 | I4: 999 | J4: 499 | K4: 199 | L4: 99 | M4: 15 | N4: 14.9 | O4: 9.9 | P4: 4.9 | Q4: 2.9 | R4: 0.99 | T4: Объем ( м3 ) | V4: 0 - 0,1 | W4: 0,11 - 0,15 | X4: 0,16 - 0,19 | Y4: 0,2 - 0,8 | Z4: 0.81 - 1,8 | AA4: 1,81 - 2,5 | AB4: 2,51 - 3 | AC4: 3,01 - 4,99 | AD4: 5 - 5,99 | AE4: 6 - 7,95 | AF4: 7,96 - 10 | AG4: 10,01 - 11,99 | AH4: 12 - 14,99 | AI4: 15 - 19,99 | AJ4: 20 - 22 | AK4: 22,01 - 34,99 | AL4: 35 - 82
A7: Исторические и исходные объёмные тарифы не загружены. Текущие веса — на листе WernerNEW.

Sheet старыеW
A1: Пункт отправления | B1: Пункт назначения | C1: Фиксированные тарифы | F1: Вес (кг) | M1: Объём (м³)
T2: Вес ( кг ) | U2: Услуга | V2: 0 - 5 | W2: 5,01 - 20 | X2: 20,01 - 41 | Y2: 41,01 -100 | Z2: 100,01 - 300 | AA2: 300,01 - 500 | AB2: 500,01 - 650 | AC2: 650,001 - 800 | AD2: 800,01 - 1000 | AE2: 1000,01 - 1500 | AF2: 1500,01 - 2000 | AG2: 2000,01 - 3000 | AH2: 3000,01 - 5000 | AI2: 5000,01 - 6000 | AJ2: 6000,01 - 8000 | AK2: 8000,01 - 10000 | AL2: 10000,01 - 20000
C3: до 5 кг | D3: до 20 кг | E3: до 40 кг | F3: от | G3: 2000- | H3: 1000- | I3: 500- | J3: 200- | K3: 100- | L3: 41 | M3: от | N3: 10- | O3: 5- | P3: 3- | Q3: 1- | R3: 0,2-
C4: до 0,03 м3 | D4: до 0,1 м3 | E4: до 0,19 м3 | F4: 3000 | G4: 2999 | H4: 1999 | I4: 999 | J4: 499 | K4: 199 | L4: 99 | M4: 15 | N4: 14.9 | O4: 9.9 | P4: 4.9 | Q4: 2.9 | R4: 0.99 | T4: Объем ( м3 ) | V4: 0 - 0,1 | W4: 0,11 - 0,15 | X4: 0,16 - 0,19 | Y4: 0,2 - 0,8 | Z4: 0.81 - 1,8 | AA4: 1,81 - 2,5 | AB4: 2,51 - 3 | AC4: 3,01 - 4,99 | AD4: 5 - 5,99 | AE4: 6 - 7,95 | AF4: 7,96 - 10 | AG4: 10,01 - 11,99 | AH4: 12 - 14,99 | AI4: 15 - 19,99 | AJ4: 20 - 22 | AK4: 22,01 - 34,99 | AL4: 35 - 82
A7: Исторические и исходные объёмные тарифы не загружены. Текущие веса — на листе WernerNEW.

Sheet Ценообразование
A7: Исторические и исходные объёмные тарифы не загружены. Текущие веса — на листе WernerNEW.

Sheet склейка
A1: № | B1: Из | C1: В | D1: Маршрут | E1: Строка
A2: 1 | B2: Москва | C2: Санкт-Петербург | D2: Москва → Санкт-Петербург | E2: 2

Sheet рабочий
C1: ='Графики'!B16&" → "&'Графики'!F16 -> Москва → Санкт-Петербург | G1: =IF(COUNTIF('склейка'!D2:D2,C1)=0,"",MATCH(C1,'склейка'!D2:D2,0)+1) -> 2
A3: Компания | C3: в | D3: 0-1кг | E3: 1-3кг | F3: 3-5кг | G3: 5-10кг | H3: 10-15кг | I3: 15-20кг | J3: 20-35кг | K3: 35-40кг | L3: 40-50кг | M3: МИН | N3: до 100 | O3: до 200 | P3: до 250 | Q3: до 300 | R3: до 400 | S3: до 500 | T3: до 600 | U3: до 700 | V3: до 750 | W3: до 800 | X3: до 1000 | Y3: до 1200 | Z3: до 1500 | AA3: до 2000 | AB3: до 2500 | AC3: до 3000 | AD3: до 5000 | AE3: до 10000 | AF3: до 20000 | AH3: 0,2-0,4 | AI3: 0,4-0,6 | AJ3: 0,6-0,8 | AK3: 0,8-1,1 | AL3: 1,1-1,2 | AM3: 1,2-1,3 | AN3: 1,3-1,5 | AO3: 1,5-1,8 | AP3: 1,8-2 | AQ3: 2-2,3 | AR3: 2,3-2,5 | AS3: 2,5-3 | AT3: 3-3,2 | AU3: 3,2-3,6 | AV3: 3,6-4 | AW3: 4--5 | AX3: 5-5,5 | AY3: 5,5-5,8 | AZ3: 5,8-6 | BA3: 6--7 | BB3: 7-7,5 | BC3: 7,5-8 | BD3: 8--10 | BE3: 10--12 | BF3: 12--15 | BG3: 15--20 | BH3: 20--25 | BI3: 25--40 | BJ3: 40--45 | BK3: 40--80
A4: WernerNEW | B4: ='Графики'!C19 -> TRUE | D4: =IF($B4=FALSE,"не выбрана",IF($G$1="","нет маршрута",INDEX('WernerNEW'!D$1:D$2,$G$1))) -> 246 | E4: =IF($B4=FALSE,"не выбрана",IF($G$1="","нет маршрута",INDEX('WernerNEW'!E$1:E$2,$G$1))) -> 246 | F4: =IF($B4=FALSE,"не выбрана",IF($G$1="","нет маршрута",INDEX('WernerNEW'!F$1:F$2,$G$1))) -> 246 | G4: =IF($B4=FALSE,"не выбрана",IF($G$1="","нет маршрута",INDEX('WernerNEW'!G$1:G$2,$G$1))) -> 453 | H4: =IF($B4=FALSE,"не выбрана",IF($G$1="","нет маршрута",INDEX('WernerNEW'!H$1:H$2,$G$1))) -> 453 | I4: =IF($B4=FALSE,"не выбрана",IF($G$1="","нет маршрута",INDEX('WernerNEW'!I$1:I$2,$G$1))) -> 453 | J4: =IF($B4=FALSE,"не выбрана",IF($G$1="","нет маршрута",INDEX('WernerNEW'!J$1:J$2,$G$1))) -> 510 | K4: =IF($B4=FALSE,"не выбрана",IF($G$1="","нет маршрута",INDEX('WernerNEW'!K$1:K$2,$G$1))) -> 570 | ... AF4: =IF($B4=FALSE,"не выбрана",IF($G$1="","нет маршрута",INDEX('WernerNEW'!AF$1:AF$2,$G$1))) -> 11.0051
A5: WernerOld | B5: ='Графики'!C20 -> FALSE | D5: =IF($B5=FALSE,"не выбрана",IF($G$1="","нет маршрута",INDEX('WernerOld'!D$1:D$2,$G$1))) -> не выбрана | E5: =IF($B5=FALSE,"не выбрана",IF($G$1="","нет маршрута",INDEX('WernerOld'!E$1:E$2,$G$1))) -> не выбрана | F5: =IF($B5=FALSE,"не выбрана",IF($G$1="","нет маршрута",INDEX('WernerOld'!F$1:F$2,$G$1))) -> не выбрана | G5: =IF($B5=FALSE,"не выбрана",IF($G$1="","нет маршрута",INDEX('WernerOld'!G$1:G$2,$G$1))) -> не выбрана | H5: =IF($B5=FALSE,"не выбрана",IF($G$1="","нет маршрута",INDEX('WernerOld'!H$1:H$2,$G$1))) -> не выбрана | I5: =IF($B5=FALSE,"не выбрана",IF($G$1="","нет маршрута",INDEX('WernerOld'!I$1:I$2,$G$1))) -> не выбрана | J5: =IF($B5=FALSE,"не выбрана",IF($G$1="","нет маршрута",INDEX('WernerOld'!J$1:J$2,$G$1))) -> не выбрана | K5: =IF($B5=FALSE,"не выбрана",IF($G$1="","нет маршрута",INDEX('WernerOld'!K$1:K$2,$G$1))) -> не выбрана | ... AF5: =IF($B5=FALSE,"не выбрана",IF($G$1="","нет маршрута",INDEX('WernerOld'!AF$1:AF$2,$G$1))) -> не выбрана
A6: ДЛ | B6: ='Графики'!C21 -> TRUE | D6: =IF($B6=FALSE,"не выбрана",IF($G$1="","нет маршрута",INDEX('ДЛ'!D$1:D$2,$G$1))) -> нет данных | E6: =IF($B6=FALSE,"не выбрана",IF($G$1="","нет маршрута",INDEX('ДЛ'!E$1:E$2,$G$1))) -> нет данных | F6: =IF($B6=FALSE,"не выбрана",IF($G$1="","нет маршрута",INDEX('ДЛ'!F$1:F$2,$G$1))) -> нет данных | G6: =IF($B6=FALSE,"не выбрана",IF($G$1="","нет маршрута",INDEX('ДЛ'!G$1:G$2,$G$1))) -> нет данных | H6: =IF($B6=FALSE,"не выбрана",IF($G$1="","нет маршрута",INDEX('ДЛ'!H$1:H$2,$G$1))) -> нет данных | I6: =IF($B6=FALSE,"не выбрана",IF($G$1="","нет маршрута",INDEX('ДЛ'!I$1:I$2,$G$1))) -> нет данных | J6: =IF($B6=FALSE,"не выбрана",IF($G$1="","нет маршрута",INDEX('ДЛ'!J$1:J$2,$G$1))) -> нет данных | K6: =IF($B6=FALSE,"не выбрана",IF($G$1="","нет маршрута",INDEX('ДЛ'!K$1:K$2,$G$1))) -> нет данных | ... AF6: =IF($B6=FALSE,"не выбрана",IF($G$1="","нет маршрута",INDEX('ДЛ'!AF$1:AF$2,$G$1))) -> нет данных
A7: ПЭК | B7: ='Графики'!C22 -> TRUE | D7: =IF($B7=FALSE,"не выбрана",IF($G$1="","нет маршрута",INDEX('ПЭК'!D$1:D$2,$G$1))) -> нет данных | E7: =IF($B7=FALSE,"не выбрана",IF($G$1="","нет маршрута",INDEX('ПЭК'!E$1:E$2,$G$1))) -> нет данных | F7: =IF($B7=FALSE,"не выбрана",IF($G$1="","нет маршрута",INDEX('ПЭК'!F$1:F$2,$G$1))) -> нет данных | G7: =IF($B7=FALSE,"не выбрана",IF($G$1="","нет маршрута",INDEX('ПЭК'!G$1:G$2,$G$1))) -> нет данных | H7: =IF($B7=FALSE,"не выбрана",IF($G$1="","нет маршрута",INDEX('ПЭК'!H$1:H$2,$G$1))) -> нет данных | I7: =IF($B7=FALSE,"не выбрана",IF($G$1="","нет маршрута",INDEX('ПЭК'!I$1:I$2,$G$1))) -> нет данных | J7: =IF($B7=FALSE,"не выбрана",IF($G$1="","нет маршрута",INDEX('ПЭК'!J$1:J$2,$G$1))) -> нет данных | K7: =IF($B7=FALSE,"не выбрана",IF($G$1="","нет маршрута",INDEX('ПЭК'!K$1:K$2,$G$1))) -> нет данных | ... AF7: =IF($B7=FALSE,"не выбрана",IF($G$1="","нет маршрута",INDEX('ПЭК'!AF$1:AF$2,$G$1))) -> нет данных
A8: КИТ | B8: ='Графики'!C23 -> TRUE | D8: =IF($B8=FALSE,"не выбрана",IF($G$1="","нет маршрута",INDEX('КИТ'!D$1:D$2,$G$1))) -> 680 | E8: =IF($B8=FALSE,"не выбрана",IF($G$1="","нет маршрута",INDEX('КИТ'!E$1:E$2,$G$1))) -> 800 | F8: =IF($B8=FALSE,"не выбрана",IF($G$1="","нет маршрута",INDEX('КИТ'!F$1:F$2,$G$1))) -> 800 | G8: =IF($B8=FALSE,"не выбрана",IF($G$1="","нет маршрута",INDEX('КИТ'!G$1:G$2,$G$1))) -> 920 | H8: =IF($B8=FALSE,"не выбрана",IF($G$1="","нет маршрута",INDEX('КИТ'!H$1:H$2,$G$1))) -> 920 | I8: =IF($B8=FALSE,"не выбрана",IF($G$1="","нет маршрута",INDEX('КИТ'!I$1:I$2,$G$1))) -> 1000 | J8: =IF($B8=FALSE,"не выбрана",IF($G$1="","нет маршрута",INDEX('КИТ'!J$1:J$2,$G$1))) -> 1000 | K8: =IF($B8=FALSE,"не выбрана",IF($G$1="","нет маршрута",INDEX('КИТ'!K$1:K$2,$G$1))) -> 732 | ... AF8: =IF($B8=FALSE,"не выбрана",IF($G$1="","нет маршрута",INDEX('КИТ'!AF$1:AF$2,$G$1))) -> 16.7
A9: Возовоз | B9: ='Графики'!C24 -> TRUE | D9: =IF($B9=FALSE,"не выбрана",IF($G$1="","нет маршрута",INDEX('Возовоз'!D$1:D$2,$G$1))) -> нет данных | E9: =IF($B9=FALSE,"не выбрана",IF($G$1="","нет маршрута",INDEX('Возовоз'!E$1:E$2,$G$1))) -> нет данных | F9: =IF($B9=FALSE,"не выбрана",IF($G$1="","нет маршрута",INDEX('Возовоз'!F$1:F$2,$G$1))) -> нет данных | G9: =IF($B9=FALSE,"не выбрана",IF($G$1="","нет маршрута",INDEX('Возовоз'!G$1:G$2,$G$1))) -> нет данных | H9: =IF($B9=FALSE,"не выбрана",IF($G$1="","нет маршрута",INDEX('Возовоз'!H$1:H$2,$G$1))) -> нет данных | I9: =IF($B9=FALSE,"не выбрана",IF($G$1="","нет маршрута",INDEX('Возовоз'!I$1:I$2,$G$1))) -> нет данных | J9: =IF($B9=FALSE,"не выбрана",IF($G$1="","нет маршрута",INDEX('Возовоз'!J$1:J$2,$G$1))) -> нет данных | K9: =IF($B9=FALSE,"не выбрана",IF($G$1="","нет маршрута",INDEX('Возовоз'!K$1:K$2,$G$1))) -> нет данных | ... AF9: =IF($B9=FALSE,"не выбрана",IF($G$1="","нет маршрута",INDEX('Возовоз'!AF$1:AF$2,$G$1))) -> нет данных
A10: Мейджик | B10: ='Графики'!C25 -> TRUE | D10: =IF($B10=FALSE,"не выбрана",IF($G$1="","нет маршрута",INDEX('Мейджик'!D$1:D$2,$G$1))) -> 500 | E10: =IF($B10=FALSE,"не выбрана",IF($G$1="","нет маршрута",INDEX('Мейджик'!E$1:E$2,$G$1))) -> 600 | F10: =IF($B10=FALSE,"не выбрана",IF($G$1="","нет маршрута",INDEX('Мейджик'!F$1:F$2,$G$1))) -> 600 | G10: =IF($B10=FALSE,"не выбрана",IF($G$1="","нет маршрута",INDEX('Мейджик'!G$1:G$2,$G$1))) -> 700 | H10: =IF($B10=FALSE,"не выбрана",IF($G$1="","нет маршрута",INDEX('Мейджик'!H$1:H$2,$G$1))) -> 700 | I10: =IF($B10=FALSE,"не выбрана",IF($G$1="","нет маршрута",INDEX('Мейджик'!I$1:I$2,$G$1))) -> 700 | J10: =IF($B10=FALSE,"не выбрана",IF($G$1="","нет маршрута",INDEX('Мейджик'!J$1:J$2,$G$1))) -> 700 | K10: =IF($B10=FALSE,"не выбрана",IF($G$1="","нет маршрута",INDEX('Мейджик'!K$1:K$2,$G$1))) -> 700 | ... AF10: =IF($B10=FALSE,"не выбрана",IF($G$1="","нет маршрута",INDEX('Мейджик'!AF$1:AF$2,$G$1))) -> 12.5
A11: Главтрасса | B11: ='Графики'!C26 -> TRUE | D11: =IF($B11=FALSE,"не выбрана",IF($G$1="","нет маршрута",INDEX('Главтрасса'!D$1:D$2,$G$1))) -> 390 | E11: =IF($B11=FALSE,"не выбрана",IF($G$1="","нет маршрута",INDEX('Главтрасса'!E$1:E$2,$G$1))) -> 390 | F11: =IF($B11=FALSE,"не выбрана",IF($G$1="","нет маршрута",INDEX('Главтрасса'!F$1:F$2,$G$1))) -> 390 | G11: =IF($B11=FALSE,"не выбрана",IF($G$1="","нет маршрута",INDEX('Главтрасса'!G$1:G$2,$G$1))) -> 400 | H11: =IF($B11=FALSE,"не выбрана",IF($G$1="","нет маршрута",INDEX('Главтрасса'!H$1:H$2,$G$1))) -> 400 | I11: =IF($B11=FALSE,"не выбрана",IF($G$1="","нет маршрута",INDEX('Главтрасса'!I$1:I$2,$G$1))) -> 400 | J11: =IF($B11=FALSE,"не выбрана",IF($G$1="","нет маршрута",INDEX('Главтрасса'!J$1:J$2,$G$1))) -> 456 | K11: =IF($B11=FALSE,"не выбрана",IF($G$1="","нет маршрута",INDEX('Главтрасса'!K$1:K$2,$G$1))) -> 550 | ... AF11: =IF($B11=FALSE,"не выбрана",IF($G$1="","нет маршрута",INDEX('Главтрасса'!AF$1:AF$2,$G$1))) -> 14.3751
A12: Пролайн | B12: ='Графики'!C27 -> TRUE | D12: =IF($B12=FALSE,"не выбрана",IF($G$1="","нет маршрута",INDEX('Пролайн'!D$1:D$2,$G$1))) -> 550 | E12: =IF($B12=FALSE,"не выбрана",IF($G$1="","нет маршрута",INDEX('Пролайн'!E$1:E$2,$G$1))) -> 550 | F12: =IF($B12=FALSE,"не выбрана",IF($G$1="","нет маршрута",INDEX('Пролайн'!F$1:F$2,$G$1))) -> 550 | G12: =IF($B12=FALSE,"не выбрана",IF($G$1="","нет маршрута",INDEX('Пролайн'!G$1:G$2,$G$1))) -> 550 | H12: =IF($B12=FALSE,"не выбрана",IF($G$1="","нет маршрута",INDEX('Пролайн'!H$1:H$2,$G$1))) -> 550 | I12: =IF($B12=FALSE,"не выбрана",IF($G$1="","нет маршрута",INDEX('Пролайн'!I$1:I$2,$G$1))) -> 550 | J12: =IF($B12=FALSE,"не выбрана",IF($G$1="","нет маршрута",INDEX('Пролайн'!J$1:J$2,$G$1))) -> 550 | K12: =IF($B12=FALSE,"не выбрана",IF($G$1="","нет маршрута",INDEX('Пролайн'!K$1:K$2,$G$1))) -> 560 | ... AF12: =IF($B12=FALSE,"не выбрана",IF($G$1="","нет маршрута",INDEX('Пролайн'!AF$1:AF$2,$G$1))) -> 12
A13: Фортуна | B13: ='Графики'!C28 -> TRUE | D13: =IF($B13=FALSE,"не выбрана",IF($G$1="","нет маршрута",INDEX('Фортуна'!D$1:D$2,$G$1))) -> 580 | E13: =IF($B13=FALSE,"не выбрана",IF($G$1="","нет маршрута",INDEX('Фортуна'!E$1:E$2,$G$1))) -> 580 | F13: =IF($B13=FALSE,"не выбрана",IF($G$1="","нет маршрута",INDEX('Фортуна'!F$1:F$2,$G$1))) -> 580 | G13: =IF($B13=FALSE,"не выбрана",IF($G$1="","нет маршрута",INDEX('Фортуна'!G$1:G$2,$G$1))) -> 580 | H13: =IF($B13=FALSE,"не выбрана",IF($G$1="","нет маршрута",INDEX('Фортуна'!H$1:H$2,$G$1))) -> 580 | I13: =IF($B13=FALSE,"не выбрана",IF($G$1="","нет маршрута",INDEX('Фортуна'!I$1:I$2,$G$1))) -> 710 | J13: =IF($B13=FALSE,"не выбрана",IF($G$1="","нет маршрута",INDEX('Фортуна'!J$1:J$2,$G$1))) -> 710 | K13: =IF($B13=FALSE,"не выбрана",IF($G$1="","нет маршрута",INDEX('Фортуна'!K$1:K$2,$G$1))) -> 710 | ... AF13: =IF($B13=FALSE,"не выбрана",IF($G$1="","нет маршрута",INDEX('Фортуна'!AF$1:AF$2,$G$1))) -> 12.1
A14: Грузопоток | B14: ='Графики'!C29 -> TRUE | D14: =IF($B14=FALSE,"не выбрана",IF($G$1="","нет маршрута",INDEX('Грузопоток'!D$1:D$2,$G$1))) -> нет данных | E14: =IF($B14=FALSE,"не выбрана",IF($G$1="","нет маршрута",INDEX('Грузопоток'!E$1:E$2,$G$1))) -> нет данных | F14: =IF($B14=FALSE,"не выбрана",IF($G$1="","нет маршрута",INDEX('Грузопоток'!F$1:F$2,$G$1))) -> нет данных | G14: =IF($B14=FALSE,"не выбрана",IF($G$1="","нет маршрута",INDEX('Грузопоток'!G$1:G$2,$G$1))) -> нет данных | H14: =IF($B14=FALSE,"не выбрана",IF($G$1="","нет маршрута",INDEX('Грузопоток'!H$1:H$2,$G$1))) -> нет данных | I14: =IF($B14=FALSE,"не выбрана",IF($G$1="","нет маршрута",INDEX('Грузопоток'!I$1:I$2,$G$1))) -> нет данных | J14: =IF($B14=FALSE,"не выбрана",IF($G$1="","нет маршрута",INDEX('Грузопоток'!J$1:J$2,$G$1))) -> нет данных | K14: =IF($B14=FALSE,"не выбрана",IF($G$1="","нет маршрута",INDEX('Грузопоток'!K$1:K$2,$G$1))) -> нет данных | ... AF14: =IF($B14=FALSE,"не выбрана",IF($G$1="","нет маршрута",INDEX('Грузопоток'!AF$1:AF$2,$G$1))) -> нет данных
A15: ФастТранс | B15: ='Графики'!C30 -> TRUE | D15: =IF($B15=FALSE,"не выбрана",IF($G$1="","нет маршрута",INDEX('ФастТранс'!D$1:D$2,$G$1))) -> 720 | E15: =IF($B15=FALSE,"не выбрана",IF($G$1="","нет маршрута",INDEX('ФастТранс'!E$1:E$2,$G$1))) -> 720 | F15: =IF($B15=FALSE,"не выбрана",IF($G$1="","нет маршрута",INDEX('ФастТранс'!F$1:F$2,$G$1))) -> 720 | G15: =IF($B15=FALSE,"не выбрана",IF($G$1="","нет маршрута",INDEX('ФастТранс'!G$1:G$2,$G$1))) -> 750 | H15: =IF($B15=FALSE,"не выбрана",IF($G$1="","нет маршрута",INDEX('ФастТранс'!H$1:H$2,$G$1))) -> 750 | I15: =IF($B15=FALSE,"не выбрана",IF($G$1="","нет маршрута",INDEX('ФастТранс'!I$1:I$2,$G$1))) -> 750 | J15: =IF($B15=FALSE,"не выбрана",IF($G$1="","нет маршрута",INDEX('ФастТранс'!J$1:J$2,$G$1))) -> 850 | K15: =IF($B15=FALSE,"не выбрана",IF($G$1="","нет маршрута",INDEX('ФастТранс'!K$1:K$2,$G$1))) -> 850 | ... AF15: =IF($B15=FALSE,"не выбрана",IF($G$1="","нет маршрута",INDEX('ФастТранс'!AF$1:AF$2,$G$1))) -> 12.8
A16: РейлКонтинент | B16: ='Графики'!C31 -> TRUE | D16: =IF($B16=FALSE,"не выбрана",IF($G$1="","нет маршрута",INDEX('РейлКонтинент'!D$1:D$2,$G$1))) -> 990 | E16: =IF($B16=FALSE,"не выбрана",IF($G$1="","нет маршрута",INDEX('РейлКонтинент'!E$1:E$2,$G$1))) -> 990 | F16: =IF($B16=FALSE,"не выбрана",IF($G$1="","нет маршрута",INDEX('РейлКонтинент'!F$1:F$2,$G$1))) -> 990 | G16: =IF($B16=FALSE,"не выбрана",IF($G$1="","нет маршрута",INDEX('РейлКонтинент'!G$1:G$2,$G$1))) -> 990 | H16: =IF($B16=FALSE,"не выбрана",IF($G$1="","нет маршрута",INDEX('РейлКонтинент'!H$1:H$2,$G$1))) -> 990 | I16: =IF($B16=FALSE,"не выбрана",IF($G$1="","нет маршрута",INDEX('РейлКонтинент'!I$1:I$2,$G$1))) -> 990 | J16: =IF($B16=FALSE,"не выбрана",IF($G$1="","нет маршрута",INDEX('РейлКонтинент'!J$1:J$2,$G$1))) -> 990 | K16: =IF($B16=FALSE,"не выбрана",IF($G$1="","нет маршрута",INDEX('РейлКонтинент'!K$1:K$2,$G$1))) -> 990 | ... AF16: =IF($B16=FALSE,"не выбрана",IF($G$1="","нет маршрута",INDEX('РейлКонтинент'!AF$1:AF$2,$G$1))) -> 15.5
A17: АТЭК | B17: ='Графики'!C32 -> TRUE | D17: =IF($B17=FALSE,"не выбрана",IF($G$1="","нет маршрута",INDEX('АТЭК'!D$1:D$2,$G$1))) -> 490 | E17: =IF($B17=FALSE,"не выбрана",IF($G$1="","нет маршрута",INDEX('АТЭК'!E$1:E$2,$G$1))) -> 490 | F17: =IF($B17=FALSE,"не выбрана",IF($G$1="","нет маршрута",INDEX('АТЭК'!F$1:F$2,$G$1))) -> 490 | G17: =IF($B17=FALSE,"не выбрана",IF($G$1="","нет маршрута",INDEX('АТЭК'!G$1:G$2,$G$1))) -> 490 | H17: =IF($B17=FALSE,"не выбрана",IF($G$1="","нет маршрута",INDEX('АТЭК'!H$1:H$2,$G$1))) -> 490 | I17: =IF($B17=FALSE,"не выбрана",IF($G$1="","нет маршрута",INDEX('АТЭК'!I$1:I$2,$G$1))) -> 490 | J17: =IF($B17=FALSE,"не выбрана",IF($G$1="","нет маршрута",INDEX('АТЭК'!J$1:J$2,$G$1))) -> 675 | K17: =IF($B17=FALSE,"не выбрана",IF($G$1="","нет маршрута",INDEX('АТЭК'!K$1:K$2,$G$1))) -> 675 | ... AF17: =IF($B17=FALSE,"не выбрана",IF($G$1="","нет маршрута",INDEX('АТЭК'!AF$1:AF$2,$G$1))) -> 10.8
A18: НоваяЛиния | B18: ='Графики'!C33 -> TRUE | D18: =IF($B18=FALSE,"не выбрана",IF($G$1="","нет маршрута",INDEX('НоваяЛиния'!D$1:D$2,$G$1))) -> 600 | E18: =IF($B18=FALSE,"не выбрана",IF($G$1="","нет маршрута",INDEX('НоваяЛиния'!E$1:E$2,$G$1))) -> 600 | F18: =IF($B18=FALSE,"не выбрана",IF($G$1="","нет маршрута",INDEX('НоваяЛиния'!F$1:F$2,$G$1))) -> 600 | G18: =IF($B18=FALSE,"не выбрана",IF($G$1="","нет маршрута",INDEX('НоваяЛиния'!G$1:G$2,$G$1))) -> 600 | H18: =IF($B18=FALSE,"не выбрана",IF($G$1="","нет маршрута",INDEX('НоваяЛиния'!H$1:H$2,$G$1))) -> 600 | I18: =IF($B18=FALSE,"не выбрана",IF($G$1="","нет маршрута",INDEX('НоваяЛиния'!I$1:I$2,$G$1))) -> 600 | J18: =IF($B18=FALSE,"не выбрана",IF($G$1="","нет маршрута",INDEX('НоваяЛиния'!J$1:J$2,$G$1))) -> 600 | K18: =IF($B18=FALSE,"не выбрана",IF($G$1="","нет маршрута",INDEX('НоваяЛиния'!K$1:K$2,$G$1))) -> 600 | ... AF18: =IF($B18=FALSE,"не выбрана",IF($G$1="","нет маршрута",INDEX('НоваяЛиния'!AF$1:AF$2,$G$1))) -> по запросу
A19: БСК | B19: ='Графики'!C34 -> TRUE | D19: =IF($B19=FALSE,"не выбрана",IF($G$1="","нет маршрута",INDEX('БСК'!D$1:D$2,$G$1))) -> 450 | E19: =IF($B19=FALSE,"не выбрана",IF($G$1="","нет маршрута",INDEX('БСК'!E$1:E$2,$G$1))) -> 450 | F19: =IF($B19=FALSE,"не выбрана",IF($G$1="","нет маршрута",INDEX('БСК'!F$1:F$2,$G$1))) -> 450 | G19: =IF($B19=FALSE,"не выбрана",IF($G$1="","нет маршрута",INDEX('БСК'!G$1:G$2,$G$1))) -> 450 | H19: =IF($B19=FALSE,"не выбрана",IF($G$1="","нет маршрута",INDEX('БСК'!H$1:H$2,$G$1))) -> 450 | I19: =IF($B19=FALSE,"не выбрана",IF($G$1="","нет маршрута",INDEX('БСК'!I$1:I$2,$G$1))) -> 450 | J19: =IF($B19=FALSE,"не выбрана",IF($G$1="","нет маршрута",INDEX('БСК'!J$1:J$2,$G$1))) -> 450 | K19: =IF($B19=FALSE,"не выбрана",IF($G$1="","нет маршрута",INDEX('БСК'!K$1:K$2,$G$1))) -> 480 | ... AF19: =IF($B19=FALSE,"не выбрана",IF($G$1="","нет маршрута",INDEX('БСК'!AF$1:AF$2,$G$1))) -> 10
A20: ЭкспедицияПлюс | B20: ='Графики'!C35 -> TRUE | D20: =IF($B20=FALSE,"не выбрана",IF($G$1="","нет маршрута",INDEX('ЭкспедицияПлюс'!D$1:D$2,$G$1))) -> 650 | E20: =IF($B20=FALSE,"не выбрана",IF($G$1="","нет маршрута",INDEX('ЭкспедицияПлюс'!E$1:E$2,$G$1))) -> 650 | F20: =IF($B20=FALSE,"не выбрана",IF($G$1="","нет маршрута",INDEX('ЭкспедицияПлюс'!F$1:F$2,$G$1))) -> 650 | G20: =IF($B20=FALSE,"не выбрана",IF($G$1="","нет маршрута",INDEX('ЭкспедицияПлюс'!G$1:G$2,$G$1))) -> 650 | H20: =IF($B20=FALSE,"не выбрана",IF($G$1="","нет маршрута",INDEX('ЭкспедицияПлюс'!H$1:H$2,$G$1))) -> 650 | I20: =IF($B20=FALSE,"не выбрана",IF($G$1="","нет маршрута",INDEX('ЭкспедицияПлюс'!I$1:I$2,$G$1))) -> 650 | J20: =IF($B20=FALSE,"не выбрана",IF($G$1="","нет маршрута",INDEX('ЭкспедицияПлюс'!J$1:J$2,$G$1))) -> 650 | K20: =IF($B20=FALSE,"не выбрана",IF($G$1="","нет маршрута",INDEX('ЭкспедицияПлюс'!K$1:K$2,$G$1))) -> 650 | ... AF20: =IF($B20=FALSE,"не выбрана",IF($G$1="","нет маршрута",INDEX('ЭкспедицияПлюс'!AF$1:AF$2,$G$1))) -> 12.9663
A21: CTSgroup | B21: ='Графики'!C36 -> TRUE | D21: =IF($B21=FALSE,"не выбрана",IF($G$1="","нет маршрута",INDEX('CTSgroup'!D$1:D$2,$G$1))) -> 300 | E21: =IF($B21=FALSE,"не выбрана",IF($G$1="","нет маршрута",INDEX('CTSgroup'!E$1:E$2,$G$1))) -> 300 | F21: =IF($B21=FALSE,"не выбрана",IF($G$1="","нет маршрута",INDEX('CTSgroup'!F$1:F$2,$G$1))) -> 300 | G21: =IF($B21=FALSE,"не выбрана",IF($G$1="","нет маршрута",INDEX('CTSgroup'!G$1:G$2,$G$1))) -> 300 | H21: =IF($B21=FALSE,"не выбрана",IF($G$1="","нет маршрута",INDEX('CTSgroup'!H$1:H$2,$G$1))) -> 300 | I21: =IF($B21=FALSE,"не выбрана",IF($G$1="","нет маршрута",INDEX('CTSgroup'!I$1:I$2,$G$1))) -> 300 | J21: =IF($B21=FALSE,"не выбрана",IF($G$1="","нет маршрута",INDEX('CTSgroup'!J$1:J$2,$G$1))) -> 346.5 | K21: =IF($B21=FALSE,"не выбрана",IF($G$1="","нет маршрута",INDEX('CTSgroup'!K$1:K$2,$G$1))) -> 396 | ... AF21: =IF($B21=FALSE,"не выбрана",IF($G$1="","нет маршрута",INDEX('CTSgroup'!AF$1:AF$2,$G$1))) -> 9
A22: Енисей | B22: ='Графики'!C37 -> FALSE | D22: =IF($B22=FALSE,"не выбрана",IF($G$1="","нет маршрута",INDEX('Енисей'!D$1:D$2,$G$1))) -> не выбрана | E22: =IF($B22=FALSE,"не выбрана",IF($G$1="","нет маршрута",INDEX('Енисей'!E$1:E$2,$G$1))) -> не выбрана | F22: =IF($B22=FALSE,"не выбрана",IF($G$1="","нет маршрута",INDEX('Енисей'!F$1:F$2,$G$1))) -> не выбрана | G22: =IF($B22=FALSE,"не выбрана",IF($G$1="","нет маршрута",INDEX('Енисей'!G$1:G$2,$G$1))) -> не выбрана | H22: =IF($B22=FALSE,"не выбрана",IF($G$1="","нет маршрута",INDEX('Енисей'!H$1:H$2,$G$1))) -> не выбрана | I22: =IF($B22=FALSE,"не выбрана",IF($G$1="","нет маршрута",INDEX('Енисей'!I$1:I$2,$G$1))) -> не выбрана | J22: =IF($B22=FALSE,"не выбрана",IF($G$1="","нет маршрута",INDEX('Енисей'!J$1:J$2,$G$1))) -> не выбрана | K22: =IF($B22=FALSE,"не выбрана",IF($G$1="","нет маршрута",INDEX('Енисей'!K$1:K$2,$G$1))) -> не выбрана | ... AF22: =IF($B22=FALSE,"не выбрана",IF($G$1="","нет маршрута",INDEX('Енисей'!AF$1:AF$2,$G$1))) -> не выбрана
A23: Терминал | B23: ='Графики'!C38 -> FALSE | D23: =IF($B23=FALSE,"не выбрана",IF($G$1="","нет маршрута",INDEX('Терминал'!D$1:D$2,$G$1))) -> не выбрана | E23: =IF($B23=FALSE,"не выбрана",IF($G$1="","нет маршрута",INDEX('Терминал'!E$1:E$2,$G$1))) -> не выбрана | F23: =IF($B23=FALSE,"не выбрана",IF($G$1="","нет маршрута",INDEX('Терминал'!F$1:F$2,$G$1))) -> не выбрана | G23: =IF($B23=FALSE,"не выбрана",IF($G$1="","нет маршрута",INDEX('Терминал'!G$1:G$2,$G$1))) -> не выбрана | H23: =IF($B23=FALSE,"не выбрана",IF($G$1="","нет маршрута",INDEX('Терминал'!H$1:H$2,$G$1))) -> не выбрана | I23: =IF($B23=FALSE,"не выбрана",IF($G$1="","нет маршрута",INDEX('Терминал'!I$1:I$2,$G$1))) -> не выбрана | J23: =IF($B23=FALSE,"не выбрана",IF($G$1="","нет маршрута",INDEX('Терминал'!J$1:J$2,$G$1))) -> не выбрана | K23: =IF($B23=FALSE,"не выбрана",IF($G$1="","нет маршрута",INDEX('Терминал'!K$1:K$2,$G$1))) -> не выбрана | ... AF23: =IF($B23=FALSE,"не выбрана",IF($G$1="","нет маршрута",INDEX('Терминал'!AF$1:AF$2,$G$1))) -> не выбрана
A24: Сибтехнотранс | B24: ='Графики'!C39 -> FALSE | D24: =IF($B24=FALSE,"не выбрана",IF($G$1="","нет маршрута",INDEX('Сибтехнотранс'!D$1:D$2,$G$1))) -> не выбрана | E24: =IF($B24=FALSE,"не выбрана",IF($G$1="","нет маршрута",INDEX('Сибтехнотранс'!E$1:E$2,$G$1))) -> не выбрана | F24: =IF($B24=FALSE,"не выбрана",IF($G$1="","нет маршрута",INDEX('Сибтехнотранс'!F$1:F$2,$G$1))) -> не выбрана | G24: =IF($B24=FALSE,"не выбрана",IF($G$1="","нет маршрута",INDEX('Сибтехнотранс'!G$1:G$2,$G$1))) -> не выбрана | H24: =IF($B24=FALSE,"не выбрана",IF($G$1="","нет маршрута",INDEX('Сибтехнотранс'!H$1:H$2,$G$1))) -> не выбрана | I24: =IF($B24=FALSE,"не выбрана",IF($G$1="","нет маршрута",INDEX('Сибтехнотранс'!I$1:I$2,$G$1))) -> не выбрана | J24: =IF($B24=FALSE,"не выбрана",IF($G$1="","нет маршрута",INDEX('Сибтехнотранс'!J$1:J$2,$G$1))) -> не выбрана | K24: =IF($B24=FALSE,"не выбрана",IF($G$1="","нет маршрута",INDEX('Сибтехнотранс'!K$1:K$2,$G$1))) -> не выбрана | ... AF24: =IF($B24=FALSE,"не выбрана",IF($G$1="","нет маршрута",INDEX('Сибтехнотранс'!AF$1:AF$2,$G$1))) -> не выбрана
A25: ИмперияАвто | B25: ='Графики'!C40 -> FALSE | D25: =IF($B25=FALSE,"не выбрана",IF($G$1="","нет маршрута",INDEX('ИмперияАвто'!D$1:D$2,$G$1))) -> не выбрана | E25: =IF($B25=FALSE,"не выбрана",IF($G$1="","нет маршрута",INDEX('ИмперияАвто'!E$1:E$2,$G$1))) -> не выбрана | F25: =IF($B25=FALSE,"не выбрана",IF($G$1="","нет маршрута",INDEX('ИмперияАвто'!F$1:F$2,$G$1))) -> не выбрана | G25: =IF($B25=FALSE,"не выбрана",IF($G$1="","нет маршрута",INDEX('ИмперияАвто'!G$1:G$2,$G$1))) -> не выбрана | H25: =IF($B25=FALSE,"не выбрана",IF($G$1="","нет маршрута",INDEX('ИмперияАвто'!H$1:H$2,$G$1))) -> не выбрана | I25: =IF($B25=FALSE,"не выбрана",IF($G$1="","нет маршрута",INDEX('ИмперияАвто'!I$1:I$2,$G$1))) -> не выбрана | J25: =IF($B25=FALSE,"не выбрана",IF($G$1="","нет маршрута",INDEX('ИмперияАвто'!J$1:J$2,$G$1))) -> не выбрана | K25: =IF($B25=FALSE,"не выбрана",IF($G$1="","нет маршрута",INDEX('ИмперияАвто'!K$1:K$2,$G$1))) -> не выбрана | ... AF25: =IF($B25=FALSE,"не выбрана",IF($G$1="","нет маршрута",INDEX('ИмперияАвто'!AF$1:AF$2,$G$1))) -> не выбрана
A26: Магистраль | B26: ='Графики'!C41 -> FALSE | D26: =IF($B26=FALSE,"не выбрана",IF($G$1="","нет маршрута",INDEX('Магистраль'!D$1:D$2,$G$1))) -> не выбрана | E26: =IF($B26=FALSE,"не выбрана",IF($G$1="","нет маршрута",INDEX('Магистраль'!E$1:E$2,$G$1))) -> не выбрана | F26: =IF($B26=FALSE,"не выбрана",IF($G$1="","нет маршрута",INDEX('Магистраль'!F$1:F$2,$G$1))) -> не выбрана | G26: =IF($B26=FALSE,"не выбрана",IF($G$1="","нет маршрута",INDEX('Магистраль'!G$1:G$2,$G$1))) -> не выбрана | H26: =IF($B26=FALSE,"не выбрана",IF($G$1="","нет маршрута",INDEX('Магистраль'!H$1:H$2,$G$1))) -> не выбрана | I26: =IF($B26=FALSE,"не выбрана",IF($G$1="","нет маршрута",INDEX('Магистраль'!I$1:I$2,$G$1))) -> не выбрана | J26: =IF($B26=FALSE,"не выбрана",IF($G$1="","нет маршрута",INDEX('Магистраль'!J$1:J$2,$G$1))) -> не выбрана | K26: =IF($B26=FALSE,"не выбрана",IF($G$1="","нет маршрута",INDEX('Магистраль'!K$1:K$2,$G$1))) -> не выбрана | ... AF26: =IF($B26=FALSE,"не выбрана",IF($G$1="","нет маршрута",INDEX('Магистраль'!AF$1:AF$2,$G$1))) -> не выбрана
A27: Транзит | B27: ='Графики'!C42 -> FALSE | D27: =IF($B27=FALSE,"не выбрана",IF($G$1="","нет маршрута",INDEX('Транзит'!D$1:D$2,$G$1))) -> не выбрана | E27: =IF($B27=FALSE,"не выбрана",IF($G$1="","нет маршрута",INDEX('Транзит'!E$1:E$2,$G$1))) -> не выбрана | F27: =IF($B27=FALSE,"не выбрана",IF($G$1="","нет маршрута",INDEX('Транзит'!F$1:F$2,$G$1))) -> не выбрана | G27: =IF($B27=FALSE,"не выбрана",IF($G$1="","нет маршрута",INDEX('Транзит'!G$1:G$2,$G$1))) -> не выбрана | H27: =IF($B27=FALSE,"не выбрана",IF($G$1="","нет маршрута",INDEX('Транзит'!H$1:H$2,$G$1))) -> не выбрана | I27: =IF($B27=FALSE,"не выбрана",IF($G$1="","нет маршрута",INDEX('Транзит'!I$1:I$2,$G$1))) -> не выбрана | J27: =IF($B27=FALSE,"не выбрана",IF($G$1="","нет маршрута",INDEX('Транзит'!J$1:J$2,$G$1))) -> не выбрана | K27: =IF($B27=FALSE,"не выбрана",IF($G$1="","нет маршрута",INDEX('Транзит'!K$1:K$2,$G$1))) -> не выбрана | ... AF27: =IF($B27=FALSE,"не выбрана",IF($G$1="","нет маршрута",INDEX('Транзит'!AF$1:AF$2,$G$1))) -> не выбрана
A28: АРТК | B28: ='Графики'!C43 -> FALSE | D28: =IF($B28=FALSE,"не выбрана",IF($G$1="","нет маршрута",INDEX('АРТК'!D$1:D$2,$G$1))) -> не выбрана | E28: =IF($B28=FALSE,"не выбрана",IF($G$1="","нет маршрута",INDEX('АРТК'!E$1:E$2,$G$1))) -> не выбрана | F28: =IF($B28=FALSE,"не выбрана",IF($G$1="","нет маршрута",INDEX('АРТК'!F$1:F$2,$G$1))) -> не выбрана | G28: =IF($B28=FALSE,"не выбрана",IF($G$1="","нет маршрута",INDEX('АРТК'!G$1:G$2,$G$1))) -> не выбрана | H28: =IF($B28=FALSE,"не выбрана",IF($G$1="","нет маршрута",INDEX('АРТК'!H$1:H$2,$G$1))) -> не выбрана | I28: =IF($B28=FALSE,"не выбрана",IF($G$1="","нет маршрута",INDEX('АРТК'!I$1:I$2,$G$1))) -> не выбрана | J28: =IF($B28=FALSE,"не выбрана",IF($G$1="","нет маршрута",INDEX('АРТК'!J$1:J$2,$G$1))) -> не выбрана | K28: =IF($B28=FALSE,"не выбрана",IF($G$1="","нет маршрута",INDEX('АРТК'!K$1:K$2,$G$1))) -> не выбрана | ... AF28: =IF($B28=FALSE,"не выбрана",IF($G$1="","нет маршрута",INDEX('АРТК'!AF$1:AF$2,$G$1))) -> не выбрана
A29: Аскор | B29: ='Графики'!C44 -> FALSE | D29: =IF($B29=FALSE,"не выбрана",IF($G$1="","нет маршрута",INDEX('Аскор'!D$1:D$2,$G$1))) -> не выбрана | E29: =IF($B29=FALSE,"не выбрана",IF($G$1="","нет маршрута",INDEX('Аскор'!E$1:E$2,$G$1))) -> не выбрана | F29: =IF($B29=FALSE,"не выбрана",IF($G$1="","нет маршрута",INDEX('Аскор'!F$1:F$2,$G$1))) -> не выбрана | G29: =IF($B29=FALSE,"не выбрана",IF($G$1="","нет маршрута",INDEX('Аскор'!G$1:G$2,$G$1))) -> не выбрана | H29: =IF($B29=FALSE,"не выбрана",IF($G$1="","нет маршрута",INDEX('Аскор'!H$1:H$2,$G$1))) -> не выбрана | I29: =IF($B29=FALSE,"не выбрана",IF($G$1="","нет маршрута",INDEX('Аскор'!I$1:I$2,$G$1))) -> не выбрана | J29: =IF($B29=FALSE,"не выбрана",IF($G$1="","нет маршрута",INDEX('Аскор'!J$1:J$2,$G$1))) -> не выбрана | K29: =IF($B29=FALSE,"не выбрана",IF($G$1="","нет маршрута",INDEX('Аскор'!K$1:K$2,$G$1))) -> не выбрана | ... AF29: =IF($B29=FALSE,"не выбрана",IF($G$1="","нет маршрута",INDEX('Аскор'!AF$1:AF$2,$G$1))) -> не выбрана
A30: КараванКарго | B30: ='Графики'!C45 -> FALSE | D30: =IF($B30=FALSE,"не выбрана",IF($G$1="","нет маршрута",INDEX('КараванКарго'!D$1:D$2,$G$1))) -> не выбрана | E30: =IF($B30=FALSE,"не выбрана",IF($G$1="","нет маршрута",INDEX('КараванКарго'!E$1:E$2,$G$1))) -> не выбрана | F30: =IF($B30=FALSE,"не выбрана",IF($G$1="","нет маршрута",INDEX('КараванКарго'!F$1:F$2,$G$1))) -> не выбрана | G30: =IF($B30=FALSE,"не выбрана",IF($G$1="","нет маршрута",INDEX('КараванКарго'!G$1:G$2,$G$1))) -> не выбрана | H30: =IF($B30=FALSE,"не выбрана",IF($G$1="","нет маршрута",INDEX('КараванКарго'!H$1:H$2,$G$1))) -> не выбрана | I30: =IF($B30=FALSE,"не выбрана",IF($G$1="","нет маршрута",INDEX('КараванКарго'!I$1:I$2,$G$1))) -> не выбрана | J30: =IF($B30=FALSE,"не выбрана",IF($G$1="","нет маршрута",INDEX('КараванКарго'!J$1:J$2,$G$1))) -> не выбрана | K30: =IF($B30=FALSE,"не выбрана",IF($G$1="","нет маршрута",INDEX('КараванКарго'!K$1:K$2,$G$1))) -> не выбрана | ... AF30: =IF($B30=FALSE,"не выбрана",IF($G$1="","нет маршрута",INDEX('КараванКарго'!AF$1:AF$2,$G$1))) -> не выбрана
A31: СолнечныйМагадан | B31: ='Графики'!C46 -> FALSE | D31: =IF($B31=FALSE,"не выбрана",IF($G$1="","нет маршрута",INDEX('СолнечныйМагадан'!D$1:D$2,$G$1))) -> не выбрана | E31: =IF($B31=FALSE,"не выбрана",IF($G$1="","нет маршрута",INDEX('СолнечныйМагадан'!E$1:E$2,$G$1))) -> не выбрана | F31: =IF($B31=FALSE,"не выбрана",IF($G$1="","нет маршрута",INDEX('СолнечныйМагадан'!F$1:F$2,$G$1))) -> не выбрана | G31: =IF($B31=FALSE,"не выбрана",IF($G$1="","нет маршрута",INDEX('СолнечныйМагадан'!G$1:G$2,$G$1))) -> не выбрана | H31: =IF($B31=FALSE,"не выбрана",IF($G$1="","нет маршрута",INDEX('СолнечныйМагадан'!H$1:H$2,$G$1))) -> не выбрана | I31: =IF($B31=FALSE,"не выбрана",IF($G$1="","нет маршрута",INDEX('СолнечныйМагадан'!I$1:I$2,$G$1))) -> не выбрана | J31: =IF($B31=FALSE,"не выбрана",IF($G$1="","нет маршрута",INDEX('СолнечныйМагадан'!J$1:J$2,$G$1))) -> не выбрана | K31: =IF($B31=FALSE,"не выбрана",IF($G$1="","нет маршрута",INDEX('СолнечныйМагадан'!K$1:K$2,$G$1))) -> не выбрана | ... AF31: =IF($B31=FALSE,"не выбрана",IF($G$1="","нет маршрута",INDEX('СолнечныйМагадан'!AF$1:AF$2,$G$1))) -> не выбрана
A32: Анкор | B32: ='Графики'!C47 -> FALSE | D32: =IF($B32=FALSE,"не выбрана",IF($G$1="","нет маршрута",INDEX('Анкор'!D$1:D$2,$G$1))) -> не выбрана | E32: =IF($B32=FALSE,"не выбрана",IF($G$1="","нет маршрута",INDEX('Анкор'!E$1:E$2,$G$1))) -> не выбрана | F32: =IF($B32=FALSE,"не выбрана",IF($G$1="","нет маршрута",INDEX('Анкор'!F$1:F$2,$G$1))) -> не выбрана | G32: =IF($B32=FALSE,"не выбрана",IF($G$1="","нет маршрута",INDEX('Анкор'!G$1:G$2,$G$1))) -> не выбрана | H32: =IF($B32=FALSE,"не выбрана",IF($G$1="","нет маршрута",INDEX('Анкор'!H$1:H$2,$G$1))) -> не выбрана | I32: =IF($B32=FALSE,"не выбрана",IF($G$1="","нет маршрута",INDEX('Анкор'!I$1:I$2,$G$1))) -> не выбрана | J32: =IF($B32=FALSE,"не выбрана",IF($G$1="","нет маршрута",INDEX('Анкор'!J$1:J$2,$G$1))) -> не выбрана | K32: =IF($B32=FALSE,"не выбрана",IF($G$1="","нет маршрута",INDEX('Анкор'!K$1:K$2,$G$1))) -> не выбрана | ... AF32: =IF($B32=FALSE,"не выбрана",IF($G$1="","нет маршрута",INDEX('Анкор'!AF$1:AF$2,$G$1))) -> не выбрана
A33: ЖелдорАльянс | B33: ='Графики'!C48 -> FALSE | D33: =IF($B33=FALSE,"не выбрана",IF($G$1="","нет маршрута",INDEX('ЖелдорАльянс'!D$1:D$2,$G$1))) -> не выбрана | E33: =IF($B33=FALSE,"не выбрана",IF($G$1="","нет маршрута",INDEX('ЖелдорАльянс'!E$1:E$2,$G$1))) -> не выбрана | F33: =IF($B33=FALSE,"не выбрана",IF($G$1="","нет маршрута",INDEX('ЖелдорАльянс'!F$1:F$2,$G$1))) -> не выбрана | G33: =IF($B33=FALSE,"не выбрана",IF($G$1="","нет маршрута",INDEX('ЖелдорАльянс'!G$1:G$2,$G$1))) -> не выбрана | H33: =IF($B33=FALSE,"не выбрана",IF($G$1="","нет маршрута",INDEX('ЖелдорАльянс'!H$1:H$2,$G$1))) -> не выбрана | I33: =IF($B33=FALSE,"не выбрана",IF($G$1="","нет маршрута",INDEX('ЖелдорАльянс'!I$1:I$2,$G$1))) -> не выбрана | J33: =IF($B33=FALSE,"не выбрана",IF($G$1="","нет маршрута",INDEX('ЖелдорАльянс'!J$1:J$2,$G$1))) -> не выбрана | K33: =IF($B33=FALSE,"не выбрана",IF($G$1="","нет маршрута",INDEX('ЖелдорАльянс'!K$1:K$2,$G$1))) -> не выбрана | ... AF33: =IF($B33=FALSE,"не выбрана",IF($G$1="","нет маршрута",INDEX('ЖелдорАльянс'!AF$1:AF$2,$G$1))) -> не выбрана
A34: ЖелдорЭкспресс | B34: ='Графики'!C49 -> FALSE | D34: =IF($B34=FALSE,"не выбрана",IF($G$1="","нет маршрута",INDEX('ЖелдорЭкспресс'!D$1:D$2,$G$1))) -> не выбрана | E34: =IF($B34=FALSE,"не выбрана",IF($G$1="","нет маршрута",INDEX('ЖелдорЭкспресс'!E$1:E$2,$G$1))) -> не выбрана | F34: =IF($B34=FALSE,"не выбрана",IF($G$1="","нет маршрута",INDEX('ЖелдорЭкспресс'!F$1:F$2,$G$1))) -> не выбрана | G34: =IF($B34=FALSE,"не выбрана",IF($G$1="","нет маршрута",INDEX('ЖелдорЭкспресс'!G$1:G$2,$G$1))) -> не выбрана | H34: =IF($B34=FALSE,"не выбрана",IF($G$1="","нет маршрута",INDEX('ЖелдорЭкспресс'!H$1:H$2,$G$1))) -> не выбрана | I34: =IF($B34=FALSE,"не выбрана",IF($G$1="","нет маршрута",INDEX('ЖелдорЭкспресс'!I$1:I$2,$G$1))) -> не выбрана | J34: =IF($B34=FALSE,"не выбрана",IF($G$1="","нет маршрута",INDEX('ЖелдорЭкспресс'!J$1:J$2,$G$1))) -> не выбрана | K34: =IF($B34=FALSE,"не выбрана",IF($G$1="","нет маршрута",INDEX('ЖелдорЭкспресс'!K$1:K$2,$G$1))) -> не выбрана | ... AF34: =IF($B34=FALSE,"не выбрана",IF($G$1="","нет маршрута",INDEX('ЖелдорЭкспресс'!AF$1:AF$2,$G$1))) -> не выбрана
A35: МТК авто | B35: ='Графики'!C50 -> FALSE | D35: =IF($B35=FALSE,"не выбрана",IF($G$1="","нет маршрута",INDEX('МТК авто'!D$1:D$2,$G$1))) -> не выбрана | E35: =IF($B35=FALSE,"не выбрана",IF($G$1="","нет маршрута",INDEX('МТК авто'!E$1:E$2,$G$1))) -> не выбрана | F35: =IF($B35=FALSE,"не выбрана",IF($G$1="","нет маршрута",INDEX('МТК авто'!F$1:F$2,$G$1))) -> не выбрана | G35: =IF($B35=FALSE,"не выбрана",IF($G$1="","нет маршрута",INDEX('МТК авто'!G$1:G$2,$G$1))) -> не выбрана | H35: =IF($B35=FALSE,"не выбрана",IF($G$1="","нет маршрута",INDEX('МТК авто'!H$1:H$2,$G$1))) -> не выбрана | I35: =IF($B35=FALSE,"не выбрана",IF($G$1="","нет маршрута",INDEX('МТК авто'!I$1:I$2,$G$1))) -> не выбрана | J35: =IF($B35=FALSE,"не выбрана",IF($G$1="","нет маршрута",INDEX('МТК авто'!J$1:J$2,$G$1))) -> не выбрана | K35: =IF($B35=FALSE,"не выбрана",IF($G$1="","нет маршрута",INDEX('МТК авто'!K$1:K$2,$G$1))) -> не выбрана | ... AF35: =IF($B35=FALSE,"не выбрана",IF($G$1="","нет маршрута",INDEX('МТК авто'!AF$1:AF$2,$G$1))) -> не выбрана
A36: МТК жд | B36: ='Графики'!C51 -> FALSE | D36: =IF($B36=FALSE,"не выбрана",IF($G$1="","нет маршрута",INDEX('МТК жд'!D$1:D$2,$G$1))) -> не выбрана | E36: =IF($B36=FALSE,"не выбрана",IF($G$1="","нет маршрута",INDEX('МТК жд'!E$1:E$2,$G$1))) -> не выбрана | F36: =IF($B36=FALSE,"не выбрана",IF($G$1="","нет маршрута",INDEX('МТК жд'!F$1:F$2,$G$1))) -> не выбрана | G36: =IF($B36=FALSE,"не выбрана",IF($G$1="","нет маршрута",INDEX('МТК жд'!G$1:G$2,$G$1))) -> не выбрана | H36: =IF($B36=FALSE,"не выбрана",IF($G$1="","нет маршрута",INDEX('МТК жд'!H$1:H$2,$G$1))) -> не выбрана | I36: =IF($B36=FALSE,"не выбрана",IF($G$1="","нет маршрута",INDEX('МТК жд'!I$1:I$2,$G$1))) -> не выбрана | J36: =IF($B36=FALSE,"не выбрана",IF($G$1="","нет маршрута",INDEX('МТК жд'!J$1:J$2,$G$1))) -> не выбрана | K36: =IF($B36=FALSE,"не выбрана",IF($G$1="","нет маршрута",INDEX('МТК жд'!K$1:K$2,$G$1))) -> не выбрана | ... AF36: =IF($B36=FALSE,"не выбрана",IF($G$1="","нет маршрута",INDEX('МТК жд'!AF$1:AF$2,$G$1))) -> не выбрана
A37: Байкал Сервис | B37: ='Графики'!C52 -> TRUE | D37: =IF($B37=FALSE,"не выбрана",IF($G$1="","нет маршрута",INDEX('Байкал Сервис'!D$1:D$2,$G$1))) -> нет данных | E37: =IF($B37=FALSE,"не выбрана",IF($G$1="","нет маршрута",INDEX('Байкал Сервис'!E$1:E$2,$G$1))) -> нет данных | F37: =IF($B37=FALSE,"не выбрана",IF($G$1="","нет маршрута",INDEX('Байкал Сервис'!F$1:F$2,$G$1))) -> нет данных | G37: =IF($B37=FALSE,"не выбрана",IF($G$1="","нет маршрута",INDEX('Байкал Сервис'!G$1:G$2,$G$1))) -> нет данных | H37: =IF($B37=FALSE,"не выбрана",IF($G$1="","нет маршрута",INDEX('Байкал Сервис'!H$1:H$2,$G$1))) -> нет данных | I37: =IF($B37=FALSE,"не выбрана",IF($G$1="","нет маршрута",INDEX('Байкал Сервис'!I$1:I$2,$G$1))) -> нет данных | J37: =IF($B37=FALSE,"не выбрана",IF($G$1="","нет маршрута",INDEX('Байкал Сервис'!J$1:J$2,$G$1))) -> нет данных | K37: =IF($B37=FALSE,"не выбрана",IF($G$1="","нет маршрута",INDEX('Байкал Сервис'!K$1:K$2,$G$1))) -> нет данных | ... AF37: =IF($B37=FALSE,"не выбрана",IF($G$1="","нет маршрута",INDEX('Байкал Сервис'!AF$1:AF$2,$G$1))) -> нет данных

Sheet WernerOld
A1: WernerOld | D1: 0-1кг | E1: 1-3кг | F1: 3-5кг | G1: 5-10кг | H1: 10-15кг | I1: 15-20кг | J1: 20-35кг | K1: 35-40кг | L1: 40-50кг | M1: МИН | N1: до 100 | O1: до 200 | P1: до 250 | Q1: до 300 | R1: до 400 | S1: до 500 | T1: до 600 | U1: до 700 | V1: до 750 | W1: до 800 | X1: до 1000 | Y1: до 1200 | Z1: до 1500 | AA1: до 2000 | AB1: до 2500 | AC1: до 3000 | AD1: до 5000 | AE1: до 10000 | AF1: до 20000 | AH1: 0,2-0,4 | AI1: 0,4-0,6 | AJ1: 0,6-0,8 | AK1: 0,8-1,1 | AL1: 1,1-1,2 | AM1: 1,2-1,3 | AN1: 1,3-1,5 | AO1: 1,5-1,8 | AP1: 1,8-2 | AQ1: 2-2,3 | AR1: 2,3-2,5 | AS1: 2,5-3 | AT1: 3-3,2 | AU1: 3,2-3,6 | AV1: 3,6-4 | AW1: 4--5 | AX1: 5-5,5 | AY1: 5,5-5,8 | AZ1: 5,8-6 | BA1: 6--7 | BB1: 7-7,5 | BC1: 7,5-8 | BD1: 8--10 | BE1: 10--12 | BF1: 12--15 | BG1: 15--20 | BH1: 20--25 | BI1: 25--40 | BJ1: 40--45 | BK1: 40--80
A2: 1 | B2: Москва | C2: Санкт-Петербург | D2: нет истории | E2: нет истории | F2: нет истории | G2: нет истории | H2: нет истории | I2: нет истории | J2: нет истории | K2: нет истории | L2: нет истории | M2: нет истории | N2: нет истории | O2: нет истории | P2: нет истории | Q2: нет истории | R2: нет истории | S2: нет истории | T2: нет истории | U2: нет истории | V2: нет истории | W2: нет истории | X2: нет истории | Y2: нет истории | Z2: нет истории | AA2: нет истории | AB2: нет истории | AC2: нет истории | AD2: нет истории | AE2: нет истории | AF2: нет истории | AH2: не собрано | AI2: не собрано | AJ2: не собрано | AK2: не собрано | AL2: не собрано | AM2: не собрано | AN2: не собрано | AO2: не собрано | AP2: не собрано | AQ2: не собрано | AR2: не собрано | AS2: не собрано | AT2: не собрано | AU2: не собрано | AV2: не собрано | AW2: не собрано | AX2: не собрано | AY2: не собрано | AZ2: не собрано | BA2: не собрано | BB2: не собрано | BC2: не собрано | BD2: не собрано | BE2: не собрано | BF2: не собрано | BG2: не собрано | BH2: не собрано | BI2: не собрано | BJ2: не собрано | BK2: не собрано
B5: D:L — отправка, ₽; M — минимум, ₽; N:AF — эффективная стоимость, ₽/кг.
B6: AH:BK — структура объёмных тарифов; эти данные приложением не собираются.

Sheet Графики
B14: Малые веса и МИН — ₽. От 100 кг — эффективные ₽/кг.
B15: Экспорт 14.09.2026 16:12
B16: Москва | F16: Санкт-Петербург
B18: Компания | C18: Включена | D18: в | E18: 0-1кг | F18: 1-3кг | G18: 3-5кг | H18: 5-10кг | I18: 10-15кг | J18: 15-20кг | K18: 20-35кг | L18: 35-40кг | M18: 40-50кг | N18: МИН | O18: до 100кг | P18: до 200кг | Q18: до 250кг | R18: до 300кг | S18: до 400кг | T18: до 500кг | U18: до 600кг | V18: до 700кг | W18: до 750кг | X18: до 800кг | Y18: до 1000кг | Z18: до 1200кг | AA18: до 1500кг | AB18: до 2000кг | AC18: до 2500кг | AD18: до 3000кг | AE18: до 5000кг | AF18: до 10000кг | AG18: до 20000кг | AI18: 0,2- 0,4 | AJ18: 0,4-0,6 | AK18: 0,6-0,8 | AL18: 0,8-1,1 | AM18: 1,1-1,2 | AN18: 1,2-1,3 | AO18: 1,3-1,5 | AP18: 1,5-1,8 | AQ18: 1,8-2 | AR18: 2-2,3 | AS18: 2,3-2,5 | AT18: 2,5-3 | AU18: 3-3,2 | AV18: 3,2-3,6 | AW18: 3,6-4 | AX18: 4--5 | AY18: 5-5,5 | AZ18: 5,5-5,8 | BA18: 5,8-6 | BB18: 6--7 | BC18: 7-7,5 | BD18: 7,5-8 | BE18: 8--10 | BF18: 10--12 | BG18: 12--15 | BH18: 15--20 | BI18: 20--25 | BJ18: 25--40 | BK18: 40--45
B19: WernerNEW | C19: TRUE | E19: ='рабочий'!D4 -> 246 | F19: ='рабочий'!E4 -> 246 | G19: ='рабочий'!F4 -> 246 | H19: ='рабочий'!G4 -> 453 | I19: ='рабочий'!H4 -> 453 | J19: ='рабочий'!I4 -> 453 | K19: ='рабочий'!J4 -> 510 | L19: ='рабочий'!K4 -> 570 | ... AG19: ='рабочий'!AF4 -> 11.0051 | AI19: не собрано | AJ19: не собрано | AK19: не собрано | AL19: не собрано | AM19: не собрано | AN19: не собрано | AO19: не собрано | AP19: не собрано | AQ19: не собрано | AR19: не собрано | AS19: не собрано | AT19: не собрано | AU19: не собрано | AV19: не собрано | AW19: не собрано | AX19: не собрано | AY19: не собрано | AZ19: не собрано | BA19: не собрано | BB19: не собрано | BC19: не собрано | BD19: не собрано | BE19: не собрано | BF19: не собрано | BG19: не собрано | BH19: не собрано | BI19: не собрано | BJ19: не собрано | BK19: не собрано | BL19: не собрано
B20: WernerOld | C20: FALSE | E20: ='рабочий'!D5 -> не выбрана | F20: ='рабочий'!E5 -> не выбрана | G20: ='рабочий'!F5 -> не выбрана | H20: ='рабочий'!G5 -> не выбрана | I20: ='рабочий'!H5 -> не выбрана | J20: ='рабочий'!I5 -> не выбрана | K20: ='рабочий'!J5 -> не выбрана | L20: ='рабочий'!K5 -> не выбрана | ... AG20: ='рабочий'!AF5 -> не выбрана | AI20: не собрано | AJ20: не собрано | AK20: не собрано | AL20: не собрано | AM20: не собрано | AN20: не собрано | AO20: не собрано | AP20: не собрано | AQ20: не собрано | AR20: не собрано | AS20: не собрано | AT20: не собрано | AU20: не собрано | AV20: не собрано | AW20: не собрано | AX20: не собрано | AY20: не собрано | AZ20: не собрано | BA20: не собрано | BB20: не собрано | BC20: не собрано | BD20: не собрано | BE20: не собрано | BF20: не собрано | BG20: не собрано | BH20: не собрано | BI20: не собрано | BJ20: не собрано | BK20: не собрано | BL20: не собрано
B21: ДЛ | C21: TRUE | E21: ='рабочий'!D6 -> нет данных | F21: ='рабочий'!E6 -> нет данных | G21: ='рабочий'!F6 -> нет данных | H21: ='рабочий'!G6 -> нет данных | I21: ='рабочий'!H6 -> нет данных | J21: ='рабочий'!I6 -> нет данных | K21: ='рабочий'!J6 -> нет данных | L21: ='рабочий'!K6 -> нет данных | ... AG21: ='рабочий'!AF6 -> нет данных | AI21: не собрано | AJ21: не собрано | AK21: не собрано | AL21: не собрано | AM21: не собрано | AN21: не собрано | AO21: не собрано | AP21: не собрано | AQ21: не собрано | AR21: не собрано | AS21: не собрано | AT21: не собрано | AU21: не собрано | AV21: не собрано | AW21: не собрано | AX21: не собрано | AY21: не собрано | AZ21: не собрано | BA21: не собрано | BB21: не собрано | BC21: не собрано | BD21: не собрано | BE21: не собрано | BF21: не собрано | BG21: не собрано | BH21: не собрано | BI21: не собрано | BJ21: не собрано | BK21: не собрано | BL21: не собрано
B22: ПЭК | C22: TRUE | E22: ='рабочий'!D7 -> нет данных | F22: ='рабочий'!E7 -> нет данных | G22: ='рабочий'!F7 -> нет данных | H22: ='рабочий'!G7 -> нет данных | I22: ='рабочий'!H7 -> нет данных | J22: ='рабочий'!I7 -> нет данных | K22: ='рабочий'!J7 -> нет данных | L22: ='рабочий'!K7 -> нет данных | ... AG22: ='рабочий'!AF7 -> нет данных | AI22: не собрано | AJ22: не собрано | AK22: не собрано | AL22: не собрано | AM22: не собрано | AN22: не собрано | AO22: не собрано | AP22: не собрано | AQ22: не собрано | AR22: не собрано | AS22: не собрано | AT22: не собрано | AU22: не собрано | AV22: не собрано | AW22: не собрано | AX22: не собрано | AY22: не собрано | AZ22: не собрано | BA22: не собрано | BB22: не собрано | BC22: не собрано | BD22: не собрано | BE22: не собрано | BF22: не собрано | BG22: не собрано | BH22: не собрано | BI22: не собрано | BJ22: не собрано | BK22: не собрано | BL22: не собрано
B23: КИТ | C23: TRUE | E23: ='рабочий'!D8 -> 680 | F23: ='рабочий'!E8 -> 800 | G23: ='рабочий'!F8 -> 800 | H23: ='рабочий'!G8 -> 920 | I23: ='рабочий'!H8 -> 920 | J23: ='рабочий'!I8 -> 1000 | K23: ='рабочий'!J8 -> 1000 | L23: ='рабочий'!K8 -> 732 | ... AG23: ='рабочий'!AF8 -> 16.7 | AI23: не собрано | AJ23: не собрано | AK23: не собрано | AL23: не собрано | AM23: не собрано | AN23: не собрано | AO23: не собрано | AP23: не собрано | AQ23: не собрано | AR23: не собрано | AS23: не собрано | AT23: не собрано | AU23: не собрано | AV23: не собрано | AW23: не собрано | AX23: не собрано | AY23: не собрано | AZ23: не собрано | BA23: не собрано | BB23: не собрано | BC23: не собрано | BD23: не собрано | BE23: не собрано | BF23: не собрано | BG23: не собрано | BH23: не собрано | BI23: не собрано | BJ23: не собрано | BK23: не собрано | BL23: не собрано
B24: Возовоз | C24: TRUE | E24: ='рабочий'!D9 -> нет данных | F24: ='рабочий'!E9 -> нет данных | G24: ='рабочий'!F9 -> нет данных | H24: ='рабочий'!G9 -> нет данных | I24: ='рабочий'!H9 -> нет данных | J24: ='рабочий'!I9 -> нет данных | K24: ='рабочий'!J9 -> нет данных | L24: ='рабочий'!K9 -> нет данных | ... AG24: ='рабочий'!AF9 -> нет данных | AI24: не собрано | AJ24: не собрано | AK24: не собрано | AL24: не собрано | AM24: не собрано | AN24: не собрано | AO24: не собрано | AP24: не собрано | AQ24: не собрано | AR24: не собрано | AS24: не собрано | AT24: не собрано | AU24: не собрано | AV24: не собрано | AW24: не собрано | AX24: не собрано | AY24: не собрано | AZ24: не собрано | BA24: не собрано | BB24: не собрано | BC24: не собрано | BD24: не собрано | BE24: не собрано | BF24: не собрано | BG24: не собрано | BH24: не собрано | BI24: не собрано | BJ24: не собрано | BK24: не собрано | BL24: не собрано
B25: Мейджик | C25: TRUE | E25: ='рабочий'!D10 -> 500 | F25: ='рабочий'!E10 -> 600 | G25: ='рабочий'!F10 -> 600 | H25: ='рабочий'!G10 -> 700 | I25: ='рабочий'!H10 -> 700 | J25: ='рабочий'!I10 -> 700 | K25: ='рабочий'!J10 -> 700 | L25: ='рабочий'!K10 -> 700 | ... AG25: ='рабочий'!AF10 -> 12.5 | AI25: не собрано | AJ25: не собрано | AK25: не собрано | AL25: не собрано | AM25: не собрано | AN25: не собрано | AO25: не собрано | AP25: не собрано | AQ25: не собрано | AR25: не собрано | AS25: не собрано | AT25: не собрано | AU25: не собрано | AV25: не собрано | AW25: не собрано | AX25: не собрано | AY25: не собрано | AZ25: не собрано | BA25: не собрано | BB25: не собрано | BC25: не собрано | BD25: не собрано | BE25: не собрано | BF25: не собрано | BG25: не собрано | BH25: не собрано | BI25: не собрано | BJ25: не собрано | BK25: не собрано | BL25: не собрано
B26: Главтрасса | C26: TRUE | E26: ='рабочий'!D11 -> 390 | F26: ='рабочий'!E11 -> 390 | G26: ='рабочий'!F11 -> 390 | H26: ='рабочий'!G11 -> 400 | I26: ='рабочий'!H11 -> 400 | J26: ='рабочий'!I11 -> 400 | K26: ='рабочий'!J11 -> 456 | L26: ='рабочий'!K11 -> 550 | ... AG26: ='рабочий'!AF11 -> 14.3751 | AI26: не собрано | AJ26: не собрано | AK26: не собрано | AL26: не собрано | AM26: не собрано | AN26: не собрано | AO26: не собрано | AP26: не собрано | AQ26: не собрано | AR26: не собрано | AS26: не собрано | AT26: не собрано | AU26: не собрано | AV26: не собрано | AW26: не собрано | AX26: не собрано | AY26: не собрано | AZ26: не собрано | BA26: не собрано | BB26: не собрано | BC26: не собрано | BD26: не собрано | BE26: не собрано | BF26: не собрано | BG26: не собрано | BH26: не собрано | BI26: не собрано | BJ26: не собрано | BK26: не собрано | BL26: не собрано
B27: Пролайн | C27: TRUE | E27: ='рабочий'!D12 -> 550 | F27: ='рабочий'!E12 -> 550 | G27: ='рабочий'!F12 -> 550 | H27: ='рабочий'!G12 -> 550 | I27: ='рабочий'!H12 -> 550 | J27: ='рабочий'!I12 -> 550 | K27: ='рабочий'!J12 -> 550 | L27: ='рабочий'!K12 -> 560 | ... AG27: ='рабочий'!AF12 -> 12 | AI27: не собрано | AJ27: не собрано | AK27: не собрано | AL27: не собрано | AM27: не собрано | AN27: не собрано | AO27: не собрано | AP27: не собрано | AQ27: не собрано | AR27: не собрано | AS27: не собрано | AT27: не собрано | AU27: не собрано | AV27: не собрано | AW27: не собрано | AX27: не собрано | AY27: не собрано | AZ27: не собрано | BA27: не собрано | BB27: не собрано | BC27: не собрано | BD27: не собрано | BE27: не собрано | BF27: не собрано | BG27: не собрано | BH27: не собрано | BI27: не собрано | BJ27: не собрано | BK27: не собрано | BL27: не собрано
B28: Фортуна | C28: TRUE | E28: ='рабочий'!D13 -> 580 | F28: ='рабочий'!E13 -> 580 | G28: ='рабочий'!F13 -> 580 | H28: ='рабочий'!G13 -> 580 | I28: ='рабочий'!H13 -> 580 | J28: ='рабочий'!I13 -> 710 | K28: ='рабочий'!J13 -> 710 | L28: ='рабочий'!K13 -> 710 | ... AG28: ='рабочий'!AF13 -> 12.1 | AI28: не собрано | AJ28: не собрано | AK28: не собрано | AL28: не собрано | AM28: не собрано | AN28: не собрано | AO28: не собрано | AP28: не собрано | AQ28: не собрано | AR28: не собрано | AS28: не собрано | AT28: не собрано | AU28: не собрано | AV28: не собрано | AW28: не собрано | AX28: не собрано | AY28: не собрано | AZ28: не собрано | BA28: не собрано | BB28: не собрано | BC28: не собрано | BD28: не собрано | BE28: не собрано | BF28: не собрано | BG28: не собрано | BH28: не собрано | BI28: не собрано | BJ28: не собрано | BK28: не собрано | BL28: не собрано
B29: Грузопоток | C29: TRUE | E29: ='рабочий'!D14 -> нет данных | F29: ='рабочий'!E14 -> нет данных | G29: ='рабочий'!F14 -> нет данных | H29: ='рабочий'!G14 -> нет данных | I29: ='рабочий'!H14 -> нет данных | J29: ='рабочий'!I14 -> нет данных | K29: ='рабочий'!J14 -> нет данных | L29: ='рабочий'!K14 -> нет данных | ... AG29: ='рабочий'!AF14 -> нет данных | AI29: не собрано | AJ29: не собрано | AK29: не собрано | AL29: не собрано | AM29: не собрано | AN29: не собрано | AO29: не собрано | AP29: не собрано | AQ29: не собрано | AR29: не собрано | AS29: не собрано | AT29: не собрано | AU29: не собрано | AV29: не собрано | AW29: не собрано | AX29: не собрано | AY29: не собрано | AZ29: не собрано | BA29: не собрано | BB29: не собрано | BC29: не собрано | BD29: не собрано | BE29: не собрано | BF29: не собрано | BG29: не собрано | BH29: не собрано | BI29: не собрано | BJ29: не собрано | BK29: не собрано | BL29: не собрано
B30: ФастТранс | C30: TRUE | E30: ='рабочий'!D15 -> 720 | F30: ='рабочий'!E15 -> 720 | G30: ='рабочий'!F15 -> 720 | H30: ='рабочий'!G15 -> 750 | I30: ='рабочий'!H15 -> 750 | J30: ='рабочий'!I15 -> 750 | K30: ='рабочий'!J15 -> 850 | L30: ='рабочий'!K15 -> 850 | ... AG30: ='рабочий'!AF15 -> 12.8 | AI30: не собрано | AJ30: не собрано | AK30: не собрано | AL30: не собрано | AM30: не собрано | AN30: не собрано | AO30: не собрано | AP30: не собрано | AQ30: не собрано | AR30: не собрано | AS30: не собрано | AT30: не собрано | AU30: не собрано | AV30: не собрано | AW30: не собрано | AX30: не собрано | AY30: не собрано | AZ30: не собрано | BA30: не собрано | BB30: не собрано | BC30: не собрано | BD30: не собрано | BE30: не собрано | BF30: не собрано | BG30: не собрано | BH30: не собрано | BI30: не собрано | BJ30: не собрано | BK30: не собрано | BL30: не собрано
... B52: Байкал Сервис | C52: TRUE | E52: ='рабочий'!D37 -> нет данных | F52: ='рабочий'!E37 -> нет данных | G52: ='рабочий'!F37 -> нет данных | H52: ='рабочий'!G37 -> нет данных | I52: ='рабочий'!H37 -> нет данных | J52: ='рабочий'!I37 -> нет данных | K52: ='рабочий'!J37 -> нет данных | L52: ='рабочий'!K37 -> нет данных | ... AG52: ='рабочий'!AF37 -> нет данных | AI52: не собрано | AJ52: не собрано | AK52: не собрано | AL52: не собрано | AM52: не собрано | AN52: не собрано | AO52: не собрано | AP52: не собрано | AQ52: не собрано | AR52: не собрано | AS52: не собрано | AT52: не собрано | AU52: не собрано | AV52: не собрано | AW52: не собрано | AX52: не собрано | AY52: не собрано | AZ52: не собрано | BA52: не собрано | BB52: не собрано | BC52: не собрано | BD52: не собрано | BE52: не собрано | BF52: не собрано | BG52: не собрано | BH52: не собрано | BI52: не собрано | BJ52: не собрано | BK52: не собрано | BL52: не собрано
B54: Онлайн-сбор: время проверки каждой строки — на листе «Источники». Старые цены и файлы пользователя не включены.
B55: Для смены маршрута выберите пару на листе «Направления» и измените B16 и F16.
B56: Для новых цен запустите «Все компании и маршруты» в приложении. Сохранённый Excel сам сайты не опрашивает.

Sheet WernerNEW
A1: WernerNEW | D1: 0-1кг | E1: 1-3кг | F1: 3-5кг | G1: 5-10кг | H1: 10-15кг | I1: 15-20кг | J1: 20-35кг | K1: 35-40кг | L1: 40-50кг | M1: МИН | N1: до 100 | O1: до 200 | P1: до 250 | Q1: до 300 | R1: до 400 | S1: до 500 | T1: до 600 | U1: до 700 | V1: до 750 | W1: до 800 | X1: до 1000 | Y1: до 1200 | Z1: до 1500 | AA1: до 2000 | AB1: до 2500 | AC1: до 3000 | AD1: до 5000 | AE1: до 10000 | AF1: до 20000 | AH1: 0,2-0,4 | AI1: 0,4-0,6 | AJ1: 0,6-0,8 | AK1: 0,8-1,1 | AL1: 1,1-1,2 | AM1: 1,2-1,3 | AN1: 1,3-1,5 | AO1: 1,5-1,8 | AP1: 1,8-2 | AQ1: 2-2,3 | AR1: 2,3-2,5 | AS1: 2,5-3 | AT1: 3-3,2 | AU1: 3,2-3,6 | AV1: 3,6-4 | AW1: 4--5 | AX1: 5-5,5 | AY1: 5,5-5,8 | AZ1: 5,8-6 | BA1: 6--7 | BB1: 7-7,5 | BC1: 7,5-8 | BD1: 8--10 | BE1: 10--12 | BF1: 12--15 | BG1: 15--20 | BH1: 20--25 | BI1: 25--40 | BJ1: 40--45 | BK1: 40--80
A2: 1 | B2: Москва | C2: Санкт-Петербург | D2: 246 | E2: 246 | F2: 246 | G2: 453 | H2: 453 | I2: 453 | J2: 510 | K2: 570 | L2: 700 | M2: 246 | N2: 14 | O2: 13.25 | P2: 13.148 | Q2: 13.0833 | R2: 13 | S2: 12.95 | T2: 12.54 | U2: 12.5186 | V2: 12.508 | W2: 12.5 | X2: 11.851 | Y2: 11.8333 | Z2: 11.816 | AA2: 11.1745 | AB2: 11.1652 | AC2: 11.0333 | AD2: 11.0198 | AE2: 11.0097 | AF2: 11.0051 | AH2: не собрано | AI2: не собрано | AJ2: не собрано | AK2: не собрано | AL2: не собрано | AM2: не собрано | AN2: не собрано | AO2: не собрано | AP2: не собрано | AQ2: не собрано | AR2: не собрано | AS2: не собрано | AT2: не собрано | AU2: не собрано | AV2: не собрано | AW2: не собрано | AX2: не собрано | AY2: не собрано | AZ2: не собрано | BA2: не собрано | BB2: не собрано | BC2: не собрано | BD2: не собрано | BE2: не собрано | BF2: не собрано | BG2: не собрано | BH2: не собрано | BI2: не собрано | BJ2: не собрано | BK2: не собрано
B5: D:L — отправка, ₽; M — минимум, ₽; N:AF — эффективная стоимость, ₽/кг.
B6: AH:BK — структура объёмных тарифов; эти данные приложением не собираются.

Sheet Направления
B1: № | C1: Из | D1: В | E1: ГП
B2: 1 | C2: Москва | D2: Санкт-Петербург | E2: Общий онлайн-сбор

Sheet ДЛ
A1: ДЛ | C1: Назначение | D1: 0-1кг | E1: 1-3кг | F1: 3-5кг | G1: 5-10кг | H1: 10-15кг | I1: 15-20кг | J1: 20-35кг | K1: 35-40кг | L1: 40-50кг | M1: МИН | N1: до 100 | O1: до 200 | P1: до 250 | Q1: до 300 | R1: до 400 | S1: до 500 | T1: до 600 | U1: до 700 | V1: до 750 | W1: до 800 | X1: до 1000 | Y1: до 1200 | Z1: до 1500 | AA1: до 2000 | AB1: до 2500 | AC1: до 3000 | AD1: до 5000 | AE1: до 10000 | AF1: до 20000 | AH1: 0,2-0,4 | AI1: 0,4-0,6 | AJ1: 0,6-0,8 | AK1: 0,8-1,1 | AL1: 1,1-1,2 | AM1: 1,2-1,3 | AN1: 1,3-1,5 | AO1: 1,5-1,8 | AP1: 1,8-2 | AQ1: 2-2,3 | AR1: 2,3-2,5 | AS1: 2,5-3 | AT1: 3-3,2 | AU1: 3,2-3,6 | AV1: 3,6-4 | AW1: 4--5 | AX1: 5-5,5 | AY1: 5,5-5,8 | AZ1: 5,8-6 | BA1: 6--7 | BB1: 7-7,5 | BC1: 7,5-8 | BD1: 8--10 | BE1: 10--12 | BF1: 12--15 | BG1: 15--20 | BH1: 20--25 | BI1: 25--40 | BJ1: 40--45 | BK1: 40--80
A2: 1 | B2: Москва | C2: Санкт-Петербург | D2: нет данных | E2: нет данных | F2: нет данных | G2: нет данных | H2: нет данных | I2: нет данных | J2: нет данных | K2: нет данных | L2: нет данных | M2: нет данных | N2: нет данных | O2: нет данных | P2: нет данных | Q2: нет данных | R2: нет данных | S2: нет данных | T2: нет данных | U2: нет данных | V2: нет данных | W2: нет данных | X2: нет данных | Y2: нет данных | Z2: нет данных | AA2: нет данных | AB2: нет данных | AC2: нет данных | AD2: нет данных | AE2: нет данных | AF2: нет данных | AH2: не собрано | AI2: не собрано | AJ2: не собрано | AK2: не собрано | AL2: не собрано | AM2: не собрано | AN2: не собрано | AO2: не собрано | AP2: не собрано | AQ2: не собрано | AR2: не собрано | AS2: не собрано | AT2: не собрано | AU2: не собрано | AV2: не собрано | AW2: не собрано | AX2: не собрано | AY2: не собрано | AZ2: не собрано | BA2: не собрано | BB2: не собрано | BC2: не собрано | BD2: не собрано | BE2: не собрано | BF2: не собрано | BG2: не собрано | BH2: не собрано | BI2: не собрано | BJ2: не собрано | BK2: не собрано
B5: D:L — отправка, ₽; M — минимум, ₽; N:AF — эффективная стоимость, ₽/кг.
B6: AH:BK — структура объёмных тарифов; эти данные приложением не собираются.

Sheet ПЭК
A1: ПЭК | C1: Назначение | D1: 0-1кг | E1: 1-3кг | F1: 3-5кг | G1: 5-10кг | H1: 10-15кг | I1: 15-20кг | J1: 20-35кг | K1: 35-40кг | L1: 40-50кг | M1: МИН | N1: до 100 | O1: до 200 | P1: до 250 | Q1: до 300 | R1: до 400 | S1: до 500 | T1: до 600 | U1: до 700 | V1: до 750 | W1: до 800 | X1: до 1000 | Y1: до 1200 | Z1: до 1500 | AA1: до 2000 | AB1: до 2500 | AC1: до 3000 | AD1: до 5000 | AE1: до 10000 | AF1: до 20000 | AH1: 0,2-0,4 | AI1: 0,4-0,6 | AJ1: 0,6-0,8 | AK1: 0,8-1,1 | AL1: 1,1-1,2 | AM1: 1,2-1,3 | AN1: 1,3-1,5 | AO1: 1,5-1,8 | AP1: 1,8-2 | AQ1: 2-2,3 | AR1: 2,3-2,5 | AS1: 2,5-3 | AT1: 3-3,2 | AU1: 3,2-3,6 | AV1: 3,6-4 | AW1: 4--5 | AX1: 5-5,5 | AY1: 5,5-5,8 | AZ1: 5,8-6 | BA1: 6--7 | BB1: 7-7,5 | BC1: 7,5-8 | BD1: 8--10 | BE1: 10--12 | BF1: 12--15 | BG1: 15--20 | BH1: 20--25 | BI1: 25--40 | BJ1: 40--45 | BK1: 40--80
